Workbook
Name AcC_row2: calc!$AC$16
Name AcC_virtual: calc!$AC$15
Name ArrayAngle: calc!$AC$6
Name ArrayDepth: 'EndFire Helper'!$S$25
Name ArrayDirection: calc!$AC$7
Name ArrayWidth: 'EndFire Helper'!$S$24
Name AvD: 'EndFire Helper'!#REF!
Name BestCancel: 'EndFire Helper'!$S$19
Name CancelF: 'EndFire Helper'!$N$15
Name distance: 'EndFire Helper'!$N$13
Name HPF: 'EndFire Helper'!$S$17
Name HPF_f: #REF!
Name LPF: 'EndFire Helper'!$S$18
Name LPF_f: #REF!
Name MainSwtch: 'EndFire Helper'!$J$2
Name OffsetRot: calc!$AC$18
Name OffsetRotDG: 'EndFire Helper'!$S$9
Name offsetT: 'EndFire Helper'!$S$8
Name OffsetVenue: calc!$N$39
Name offsetX: 'EndFire Helper'!$S$6
Name offsetY: 'EndFire Helper'!$S$7
Name Option: 'EndFire Helper'!#REF!
Name RotateSpkr: 'EndFire Helper'!$N$10
Name Single_splay: calc!$AC$14
Name sos: 'EndFire Helper'!$N$3
Name Spacing_row1: 'EndFire Helper'!$N$9
Name Spkr_in_row1: calc!$AC$5
Name temperature: 'EndFire Helper'!$N$2
Name time: 'EndFire Helper'!$N$14
Name userAngle: 'EndFire Helper'!$N$7
Name userDirection: 'EndFire Helper'!$N$11
Name userSpkr: 'EndFire Helper'!$N$6
Name VenueDepth: 'EndFire Helper'!$S$30
Name VenueWidth: 'EndFire Helper'!$S$29
Name WindowPadding: calc!$N$45

Sheet EndFire Helper
B2: Little EndFire Helper | H2: Speaker position | J2: 2 | K2: 1) arc | M2: Temperature | N2: 20 | O2: °C
K3: 2) line | M3: Speed of sound | N3: =331.5+0.606*temperature -> 343.62 | O3: m/s
B5: id | E5: ROW 1 | H5: ROW 2 | K5: R1 vs R2 | M5: Array | R5: Offsets
D6: Rotation | E6: X | F6: Y | G6: delay | H6: X | I6: Y | J6: delay | K6: 1/4 λ | M6: Speakers in row | N6: 6 | O6: =IF(Spkr_in_row1>12,"the limit is 12","") | R6: X | S6: 0 | T6: m
D7: [dg] | E7: [m] | F7: [m] | G7: [ms] | H7: [m] | I7: [m] | J7: [ms] | K7: [Hz] | M7: Array angle | N7: 57 | O7: =IF(AND(ArrayAngle>120,MainSwtch=2),"don’t go over 120dg","dg") -> dg | R7: Y | S7: 0 | T7: m
B8: L | C8: =IF(calc!$Z7=1,calc!C7,"") | D8: =IF(calc!$Z7=1,calc!D25,"") | E8: =IF(calc!$Z7=1,(IF(ArrayAngle<=0,calc!F25,IF(MainSwtch=1,calc!L25,(IF(MainSwtch=2,calc!S25,"ehm?"))))),"") | F8: =IF(calc!$Z7=1,(IF(ArrayAngle<=0,calc!G25,IF(MainSwtch=1,calc!M25,(IF(MainSwtch=2,calc!T25,"ehm?"))))),"") | G8: =IF(calc!$Z7=1,(IF(ArrayAngle<=0,calc!H25,IF(MainSwtch=1,calc!N25,(IF(MainSwtch=2,calc!U25,"ehm?"))))),"") | H8: =IF(calc!$Z7=1,(IF(ArrayAngle<=0,calc!I25,IF(MainSwtch=1,calc!O25,(IF(MainSwtch=2,calc!V25,"ehm?"))))),"") | I8: =IF(calc!$Z7=1,(IF(ArrayAngle<=0,calc!J25,IF(MainSwtch=1,calc!P25,(IF(MainSwtch=2,calc!W25,"ehm?"))))),"") | J8: =IF(calc!$Z7=1,(IF(ArrayAngle<=0,calc!K25,IF(MainSwtch=1,calc!Q25,(IF(MainSwtch=2,calc!X25,"ehm?"))))),"") | K8: =IF(calc!$Z7=1,IF(OR(ArrayAngle<=0,MainSwtch=1),calc!F43,IF(MainSwtch=2, calc!I43,"")),"") | M8: FAR | N8: =IF(ArrayAngle=0,"∞",1/SIN(RADIANS(ArrayAngle/2))) -> 2.0957385 | R8: Delay | S8: 0 | T8: ms
C9: =IF(calc!$Z8=1,calc!C8,"") | D9: =IF(calc!$Z8=1,calc!D26,"") | E9: =IF(calc!$Z8=1,(IF(ArrayAngle<=0,calc!F26,IF(MainSwtch=1,calc!L26,(IF(MainSwtch=2,calc!S26,"ehm?"))))),"") | F9: =IF(calc!$Z8=1,(IF(ArrayAngle<=0,calc!G26,IF(MainSwtch=1,calc!M26,(IF(MainSwtch=2,calc!T26,"ehm?"))))),"") | G9: =IF(calc!$Z8=1,(IF(ArrayAngle<=0,calc!H26,IF(MainSwtch=1,calc!N26,(IF(MainSwtch=2,calc!U26,"ehm?"))))),"") | H9: =IF(calc!$Z8=1,(IF(ArrayAngle<=0,calc!I26,IF(MainSwtch=1,calc!O26,(IF(MainSwtch=2,calc!V26,"ehm?"))))),"") | I9: =IF(calc!$Z8=1,(IF(ArrayAngle<=0,calc!J26,IF(MainSwtch=1,calc!P26,(IF(MainSwtch=2,calc!W26,"ehm?"))))),"") | J9: =IF(calc!$Z8=1,(IF(ArrayAngle<=0,calc!K26,IF(MainSwtch=1,calc!Q26,(IF(MainSwtch=2,calc!X26,"ehm?"))))),"") | K9: =IF(calc!$Z8=1,IF(OR(ArrayAngle<=0,MainSwtch=1),calc!F44,IF(MainSwtch=2, calc!I44,"")),"") | M9: Spacing row 1 | N9: 2 | O9: m | R9: Rotation | S9: 0 | T9: dg
C10: =IF(calc!$Z9=1,calc!C9,"") | D10: =IF(calc!$Z9=1,calc!D27,"") | E10: =IF(calc!$Z9=1,(IF(ArrayAngle<=0,calc!F27,IF(MainSwtch=1,calc!L27,(IF(MainSwtch=2,calc!S27,"ehm?"))))),"") | F10: =IF(calc!$Z9=1,(IF(ArrayAngle<=0,calc!G27,IF(MainSwtch=1,calc!M27,(IF(MainSwtch=2,calc!T27,"ehm?"))))),"") | G10: =IF(calc!$Z9=1,(IF(ArrayAngle<=0,calc!H27,IF(MainSwtch=1,calc!N27,(IF(MainSwtch=2,calc!U27,"ehm?"))))),"") | H10: =IF(calc!$Z9=1,(IF(ArrayAngle<=0,calc!I27,IF(MainSwtch=1,calc!O27,(IF(MainSwtch=2,calc!V27,"ehm?"))))),"") | I10: =IF(calc!$Z9=1,(IF(ArrayAngle<=0,calc!J27,IF(MainSwtch=1,calc!P27,(IF(MainSwtch=2,calc!W27,"ehm?"))))),"") | J10: =IF(calc!$Z9=1,(IF(ArrayAngle<=0,calc!K27,IF(MainSwtch=1,calc!Q27,(IF(MainSwtch=2,calc!X27,"ehm?"))))),"") | K10: =IF(calc!$Z9=1,IF(OR(ArrayAngle<=0,MainSwtch=1),calc!F45,IF(MainSwtch=2, calc!I45,"")),"") | M10: Speaker Rotation | N10: 100 | O10: %
C11: =IF(calc!$Z10=1,calc!C10,"") -> 3 | D11: =IF(calc!$Z10=1,calc!D28,"") -> 28.5 | E11: =IF(calc!$Z10=1,(IF(ArrayAngle<=0,calc!F28,IF(MainSwtch=1,calc!L28,(IF(MainSwtch=2,calc!S28,"ehm?"))))),"") -> 0 | F11: =IF(calc!$Z10=1,(IF(ArrayAngle<=0,calc!G28,IF(MainSwtch=1,calc!M28,(IF(MainSwtch=2,calc!T28,"ehm?"))))),"") -> 5 | G11: =IF(calc!$Z10=1,(IF(ArrayAngle<=0,calc!H28,IF(MainSwtch=1,calc!N28,(IF(MainSwtch=2,calc!U28,"ehm?"))))),"") -> 3.5941556 | H11: =IF(calc!$Z10=1,(IF(ArrayAngle<=0,calc!I28,IF(MainSwtch=1,calc!O28,(IF(MainSwtch=2,calc!V28,"ehm?"))))),"") -> 1.5 | I11: =IF(calc!$Z10=1,(IF(ArrayAngle<=0,calc!J28,IF(MainSwtch=1,calc!P28,(IF(MainSwtch=2,calc!W28,"ehm?"))))),"") -> 5.6786946 | J11: =IF(calc!$Z10=1,(IF(ArrayAngle<=0,calc!K28,IF(MainSwtch=1,calc!Q28,(IF(MainSwtch=2,calc!X28,"ehm?"))))),"") -> 8.5613862 | K11: =IF(calc!$Z10=1,IF(OR(ArrayAngle<=0,MainSwtch=1),calc!F46,IF(MainSwtch=2, calc!I46,"")),"") -> 52.177541 | R11: Tool: Distance 4 cancel
C12: =IF(calc!$Z11=1,calc!C11,"") -> 2 | D12: =IF(calc!$Z11=1,calc!D29,"") -> 17.1 | E12: =IF(calc!$Z11=1,(IF(ArrayAngle<=0,calc!F29,IF(MainSwtch=1,calc!L29,(IF(MainSwtch=2,calc!S29,"ehm?"))))),"") -> 0 | F12: =IF(calc!$Z11=1,(IF(ArrayAngle<=0,calc!G29,IF(MainSwtch=1,calc!M29,(IF(MainSwtch=2,calc!T29,"ehm?"))))),"") -> 3 | G12: =IF(calc!$Z11=1,(IF(ArrayAngle<=0,calc!H29,IF(MainSwtch=1,calc!N29,(IF(MainSwtch=2,calc!U29,"ehm?"))))),"") -> 1.2996053 | H12: =IF(calc!$Z11=1,(IF(ArrayAngle<=0,calc!I29,IF(MainSwtch=1,calc!O29,(IF(MainSwtch=2,calc!V29,"ehm?"))))),"") -> 1.5 | I12: =IF(calc!$Z11=1,(IF(ArrayAngle<=0,calc!J29,IF(MainSwtch=1,calc!P29,(IF(MainSwtch=2,calc!W29,"ehm?"))))),"") -> 3.4072168 | J12: =IF(calc!$Z11=1,(IF(ArrayAngle<=0,calc!K29,IF(MainSwtch=1,calc!Q29,(IF(MainSwtch=2,calc!X29,"ehm?"))))),"") -> 5.8667942 | K12: =IF(calc!$Z11=1,IF(OR(ArrayAngle<=0,MainSwtch=1),calc!F47,IF(MainSwtch=2, calc!I47,"")),"") -> 55.269516 | M12: End Fire | R12: Distance | S12: =sos*S13/1000 -> 1.0738125 | T12: m
C13: =IF(calc!$Z12=1,calc!C12,"") -> 1 | D13: =IF(calc!$Z12=1,calc!D30,"") -> 5.7 | E13: =IF(calc!$Z12=1,(IF(ArrayAngle<=0,calc!F30,IF(MainSwtch=1,calc!L30,(IF(MainSwtch=2,calc!S30,"ehm?"))))),"") -> 0 | F13: =IF(calc!$Z12=1,(IF(ArrayAngle<=0,calc!G30,IF(MainSwtch=1,calc!M30,(IF(MainSwtch=2,calc!T30,"ehm?"))))),"") -> 1 | G13: =IF(calc!$Z12=1,(IF(ArrayAngle<=0,calc!H30,IF(MainSwtch=1,calc!N30,(IF(MainSwtch=2,calc!U30,"ehm?"))))),"") -> 0 | H13: =IF(calc!$Z12=1,(IF(ArrayAngle<=0,calc!I30,IF(MainSwtch=1,calc!O30,(IF(MainSwtch=2,calc!V30,"ehm?"))))),"") -> 1.5 | I13: =IF(calc!$Z12=1,(IF(ArrayAngle<=0,calc!J30,IF(MainSwtch=1,calc!P30,(IF(MainSwtch=2,calc!W30,"ehm?"))))),"") -> 1.1357389 | J13: =IF(calc!$Z12=1,(IF(ArrayAngle<=0,calc!K30,IF(MainSwtch=1,calc!Q30,(IF(MainSwtch=2,calc!X30,"ehm?"))))),"") -> 4.3869783 | K13: =IF(calc!$Z12=1,IF(OR(ArrayAngle<=0,MainSwtch=1),calc!F48,IF(MainSwtch=2, calc!I48,"")),"") -> 57.036941 | M13: Distance | N13: 1.5 | O13: m | R13: Delay | S13: =(1000/S14/4) -> 3.125 | T13: ms
B14: R | C14: =IF(calc!$Z13=1,calc!C13,"") -> 1 | D14: =IF(calc!$Z13=1,calc!D31,"") -> -5.7 | E14: =IF(calc!$Z13=1,(IF(ArrayAngle<=0,calc!F31,IF(MainSwtch=1,calc!L31,(IF(MainSwtch=2,calc!S31,"ehm?"))))),"") -> 0 | F14: =IF(calc!$Z13=1,(IF(ArrayAngle<=0,calc!G31,IF(MainSwtch=1,calc!M31,(IF(MainSwtch=2,calc!T31,"ehm?"))))),"") -> -1 | G14: =IF(calc!$Z13=1,(IF(ArrayAngle<=0,calc!H31,IF(MainSwtch=1,calc!N31,(IF(MainSwtch=2,calc!U31,"ehm?"))))),"") -> 0 | H14: =IF(calc!$Z13=1,(IF(ArrayAngle<=0,calc!I31,IF(MainSwtch=1,calc!O31,(IF(MainSwtch=2,calc!V31,"ehm?"))))),"") -> 1.5 | I14: =IF(calc!$Z13=1,(IF(ArrayAngle<=0,calc!J31,IF(MainSwtch=1,calc!P31,(IF(MainSwtch=2,calc!W31,"ehm?"))))),"") -> -1.1357389 | J14: =IF(calc!$Z13=1,(IF(ArrayAngle<=0,calc!K31,IF(MainSwtch=1,calc!Q31,(IF(MainSwtch=2,calc!X31,"ehm?"))))),"") -> 4.3869783 | K14: =IF(calc!$Z13=1,IF(OR(ArrayAngle<=0,MainSwtch=1),calc!F49,IF(MainSwtch=2, calc!I49,"")),"") -> 57.036941 | M14: Delay | N14: =(1000*distance)/sos -> 4.3652872 | O14: ms | R14: Cancelation | S14: 80 | T14: Hz
C15: =IF(calc!$Z14=1,calc!C14,"") -> 2 | D15: =IF(calc!$Z14=1,calc!D32,"") -> -17.1 | E15: =IF(calc!$Z14=1,(IF(ArrayAngle<=0,calc!F32,IF(MainSwtch=1,calc!L32,(IF(MainSwtch=2,calc!S32,"ehm?"))))),"") -> 0 | F15: =IF(calc!$Z14=1,(IF(ArrayAngle<=0,calc!G32,IF(MainSwtch=1,calc!M32,(IF(MainSwtch=2,calc!T32,"ehm?"))))),"") -> -3 | G15: =IF(calc!$Z14=1,(IF(ArrayAngle<=0,calc!H32,IF(MainSwtch=1,calc!N32,(IF(MainSwtch=2,calc!U32,"ehm?"))))),"") -> 1.2996053 | H15: =IF(calc!$Z14=1,(IF(ArrayAngle<=0,calc!I32,IF(MainSwtch=1,calc!O32,(IF(MainSwtch=2,calc!V32,"ehm?"))))),"") -> 1.5 | I15: =IF(calc!$Z14=1,(IF(ArrayAngle<=0,calc!J32,IF(MainSwtch=1,calc!P32,(IF(MainSwtch=2,calc!W32,"ehm?"))))),"") -> -3.4072168 | J15: =IF(calc!$Z14=1,(IF(ArrayAngle<=0,calc!K32,IF(MainSwtch=1,calc!Q32,(IF(MainSwtch=2,calc!X32,"ehm?"))))),"") -> 5.8667942 | K15: =IF(calc!$Z14=1,IF(OR(ArrayAngle<=0,MainSwtch=1),calc!F50,IF(MainSwtch=2, calc!I50,"")),"") -> 55.269516 | M15: Cancelation | N15: =1000/(time*4) -> 57.27 | O15: Hz
C16: =IF(calc!$Z15=1,calc!C15,"") -> 3 | D16: =IF(calc!$Z15=1,calc!D33,"") -> -28.5 | E16: =IF(calc!$Z15=1,(IF(ArrayAngle<=0,calc!F33,IF(MainSwtch=1,calc!L33,(IF(MainSwtch=2,calc!S33,"ehm?"))))),"") -> 0 | F16: =IF(calc!$Z15=1,(IF(ArrayAngle<=0,calc!G33,IF(MainSwtch=1,calc!M33,(IF(MainSwtch=2,calc!T33,"ehm?"))))),"") -> -5 | G16: =IF(calc!$Z15=1,(IF(ArrayAngle<=0,calc!H33,IF(MainSwtch=1,calc!N33,(IF(MainSwtch=2,calc!U33,"ehm?"))))),"") -> 3.5941556 | H16: =IF(calc!$Z15=1,(IF(ArrayAngle<=0,calc!I33,IF(MainSwtch=1,calc!O33,(IF(MainSwtch=2,calc!V33,"ehm?"))))),"") -> 1.5 | I16: =IF(calc!$Z15=1,(IF(ArrayAngle<=0,calc!J33,IF(MainSwtch=1,calc!P33,(IF(MainSwtch=2,calc!W33,"ehm?"))))),"") -> -5.6786946 | J16: =IF(calc!$Z15=1,(IF(ArrayAngle<=0,calc!K33,IF(MainSwtch=1,calc!Q33,(IF(MainSwtch=2,calc!X33,"ehm?"))))),"") -> 8.5613862 | K16: =IF(calc!$Z15=1,IF(OR(ArrayAngle<=0,MainSwtch=1),calc!F51,IF(MainSwtch=2, calc!I51,"")),"") -> 52.177541 | R16: Tool: Cancel 4 XOver
C17: =IF(calc!$Z16=1,calc!C16,"") | D17: =IF(calc!$Z16=1,calc!D34,"") | E17: =IF(calc!$Z16=1,(IF(ArrayAngle<=0,calc!F34,IF(MainSwtch=1,calc!L34,(IF(MainSwtch=2,calc!S34,"ehm?"))))),"") | F17: =IF(calc!$Z16=1,(IF(ArrayAngle<=0,calc!G34,IF(MainSwtch=1,calc!M34,(IF(MainSwtch=2,calc!T34,"ehm?"))))),"") | G17: =IF(calc!$Z16=1,(IF(ArrayAngle<=0,calc!H34,IF(MainSwtch=1,calc!N34,(IF(MainSwtch=2,calc!U34,"ehm?"))))),"") | H17: =IF(calc!$Z16=1,(IF(ArrayAngle<=0,calc!I34,IF(MainSwtch=1,calc!O34,(IF(MainSwtch=2,calc!V34,"ehm?"))))),"") | I17: =IF(calc!$Z16=1,(IF(ArrayAngle<=0,calc!J34,IF(MainSwtch=1,calc!P34,(IF(MainSwtch=2,calc!W34,"ehm?"))))),"") | J17: =IF(calc!$Z16=1,(IF(ArrayAngle<=0,calc!K34,IF(MainSwtch=1,calc!Q34,(IF(MainSwtch=2,calc!X34,"ehm?"))))),"") | K17: =IF(calc!$Z16=1,IF(OR(ArrayAngle<=0,MainSwtch=1),calc!F52,IF(MainSwtch=2, calc!I52,"")),"") | M17: Critical f | N17: =2*CancelF -> 114.54 | O17: Hz | R17: HPF | S17: 27 | T17: Hz
C18: =IF(calc!$Z17=1,calc!C17,"") | D18: =IF(calc!$Z17=1,calc!D35,"") | E18: =IF(calc!$Z17=1,(IF(ArrayAngle<=0,calc!F35,IF(MainSwtch=1,calc!L35,(IF(MainSwtch=2,calc!S35,"ehm?"))))),"") | F18: =IF(calc!$Z17=1,(IF(ArrayAngle<=0,calc!G35,IF(MainSwtch=1,calc!M35,(IF(MainSwtch=2,calc!T35,"ehm?"))))),"") | G18: =IF(calc!$Z17=1,(IF(ArrayAngle<=0,calc!H35,IF(MainSwtch=1,calc!N35,(IF(MainSwtch=2,calc!U35,"ehm?"))))),"") | H18: =IF(calc!$Z17=1,(IF(ArrayAngle<=0,calc!I35,IF(MainSwtch=1,calc!O35,(IF(MainSwtch=2,calc!V35,"ehm?"))))),"") | I18: =IF(calc!$Z17=1,(IF(ArrayAngle<=0,calc!J35,IF(MainSwtch=1,calc!P35,(IF(MainSwtch=2,calc!W35,"ehm?"))))),"") | J18: =IF(calc!$Z17=1,(IF(ArrayAngle<=0,calc!K35,IF(MainSwtch=1,calc!Q35,(IF(MainSwtch=2,calc!X35,"ehm?"))))),"") | K18: =IF(calc!$Z17=1,IF(OR(ArrayAngle<=0,MainSwtch=1),calc!F53,IF(MainSwtch=2, calc!I53,"")),"") | M18: LF -6dB | N18: =CancelF*(55/85) -> 37.057059 | O18: Hz | R18: LPF | S18: 70 | T18: Hz
C19: =IF(calc!$Z18=1,calc!C18,"") | D19: =IF(calc!$Z18=1,calc!D36,"") | E19: =IF(calc!$Z18=1,(IF(ArrayAngle<=0,calc!F36,IF(MainSwtch=1,calc!L36,(IF(MainSwtch=2,calc!S36,"ehm?"))))),"") | F19: =IF(calc!$Z18=1,(IF(ArrayAngle<=0,calc!G36,IF(MainSwtch=1,calc!M36,(IF(MainSwtch=2,calc!T36,"ehm?"))))),"") | G19: =IF(calc!$Z18=1,(IF(ArrayAngle<=0,calc!H36,IF(MainSwtch=1,calc!N36,(IF(MainSwtch=2,calc!U36,"ehm?"))))),"") | H19: =IF(calc!$Z18=1,(IF(ArrayAngle<=0,calc!I36,IF(MainSwtch=1,calc!O36,(IF(MainSwtch=2,calc!V36,"ehm?"))))),"") | I19: =IF(calc!$Z18=1,(IF(ArrayAngle<=0,calc!J36,IF(MainSwtch=1,calc!P36,(IF(MainSwtch=2,calc!W36,"ehm?"))))),"") | J19: =IF(calc!$Z18=1,(IF(ArrayAngle<=0,calc!K36,IF(MainSwtch=1,calc!Q36,(IF(MainSwtch=2,calc!X36,"ehm?"))))),"") | K19: =IF(calc!$Z18=1,IF(OR(ArrayAngle<=0,MainSwtch=1),calc!F54,IF(MainSwtch=2, calc!I54,"")),"") | M19: HF -6dB | N19: =CancelF*(113/85) -> 76.135412 | O19: Hz | R19: Max cancelation | S19: =(LPF-HPF)/2+HPF -> 48.5 | T19: Hz
R20: Distance | S20: =sos/(S19*4) -> 1.7712371 | T20: m
D21: Total speakers | F21: =Spkr_in_row1*2 -> 12
D22: Total dsp channels | F22: =IF(ArrayAngle<=0,2,IF(MainSwtch=2,Spkr_in_row1+MOD(Spkr_in_row1,2),2)) -> 6
M23: Array info | N23: Row 1 | O23: Row 2 | R23: Dimensions
M24: Spacing | N24: =IF(Spkr_in_row1<=1,0,calc!AG5) -> 2 | O24: =IF(Spkr_in_row1<=1,0,IF(ArrayAngle<=0,N24,IF(MainSwtch=1,calc!AI5,IF(MainSwtch=2,calc!AH5,"")))) -> 2.2714778 | R24: Array width | S24: =MAX(I8:I19)-MIN(I8:I19) -> 11.357389 | T24: m
M25: λ | N25: =IF(Spkr_in_row1<=1,0,calc!AG6) -> 171.81 | O25: =IF(Spkr_in_row1<=1,0,IF(ArrayAngle<=0,N25,IF(MainSwtch=1,calc!AI6,IF(MainSwtch=2,calc!AH6,"")))) -> 151.27596 | R25: Array depth | S25: =MAX(H8:H19)-MIN(E8:E19) -> 1.5 | T25: m
M26: 2/3 λ | N26: =IF(Spkr_in_row1<=1,0,calc!AG7) -> 114.54 | O26: =IF(Spkr_in_row1<=1,0,IF(ArrayAngle<=0,N26,IF(MainSwtch=1,calc!AI7,IF(MainSwtch=2,calc!AH7,"")))) -> 100.85064
M27: 1/2 λ | N27: =IF(Spkr_in_row1<=1,0,calc!AG8) -> 85.905 | O27: =IF(Spkr_in_row1<=1,0,IF(ArrayAngle<=0,N27,IF(MainSwtch=1,calc!AI8,IF(MainSwtch=2,calc!AH8,"")))) -> 75.637982
R28: Venue
M29: Array length | N29: =IF(Spkr_in_row1<=1,0,calc!AG10) -> 10 | O29: =IF(Spkr_in_row1<=1,0,IF(ArrayAngle<=0,N29,IF(MainSwtch=1,calc!AI10,IF(MainSwtch=2,calc!AH10,"")))) -> 11.357389 | R29: width | S29: 20 | T29: m
M30: λ | N30: =IF(Spkr_in_row1<=1,0,calc!AG11) -> 34.362 | O30: =IF(Spkr_in_row1<=1,0,IF(ArrayAngle<=0,N30,IF(MainSwtch=1,calc!AI11,IF(MainSwtch=2,calc!AH11,"")))) -> 30.255193 | R30: length | S30: 60 | T30: m
R31: FAR | S31: =IF(OR(S29<=0,S30<=0),0,S30/S29) -> 3

Sheet calc
B3: Little EndFire helper
B4: id | F4: row1 0dg | I4: row2 0dg | L4: physical row1 | O4: physical row2 | S4: ROW 1 | V4: ROW 2 | Z4: consider | AG4: Row 1 | AH4: Row 2 | AI4: Row 2 Physical
D5: rotation | F5: X | G5: Y | H5: delay | I5: X | J5: Y | K5: delay | L5: X | M5: Y | N5: delay | O5: X | P5: Y | Q5: delay | R5: dist 2 r1 | S5: X | T5: Y | U5: delay | V5: X | W5: Y | X5: delay | Y5: level | AB5: Speakers in row | AC5: =userSpkr-MOD(userSpkr,1) -> 6 | AD5: =IF(Spkr_in_row1>12,"the limit is 12","") | AF5: Spacing | AG5: =Spacing_row1 -> 2 | AH5: =calc!W7-calc!W8 -> 2.2714778 | AI5: =(-AcC_virtual+distance)*RADIANS(Single_splay) -> 2.2984513 | AJ5: m
D6: [dg] | E6: [rad] | F6: [m] | G6: [m] | H6: [ms] | I6: [m] | J6: [m] | K6: [ms] | L6: [m] | M6: [m] | N6: [ms] | O6: [m] | P6: [m] | Q6: [ms] | R6: [m] | S6: [m] | T6: [m] | U6: [ms] | V6: [m] | W6: [m] | X6: [ms] | Y6: [dB] | AB6: Array angle | AC6: =userAngle -> 57 | AD6: =IF(AND(ArrayAngle>120,MainSwtch=2),"don’t go over 120dg","dg") -> dg | AF6: λ | AG6: =sos/AG5 -> 171.81 | AH6: =sos/AH5 -> 151.27596 | AI6: =sos/AI5 -> 149.50067 | AJ6: Hz
B7: L | C7: =IF(MOD(Spkr_in_row1,2)=1,5,6) -> 6 | D7: =D8+Single_splay -> 62.7 | E7: =RADIANS(D7) -> 1.0943214 | F7: 0 | G7: =G8+Spacing_row1 -> 11 | H7: 0 | I7: =distance -> 1.5 | J7: =G7 -> 11 | K7: =distance*1000/sos -> 4.3652872 | L7: =ABS(AcC_virtual)*COS($E7)+AcC_virtual -> -5.4415957 | M7: =ABS(AcC_virtual)*SIN($E7) -> 8.9322837 | N7: 0 | O7: =ABS(AcC_virtual-distance)*COS($E7)+AcC_virtual -> -4.7536214 | P7: =ABS(AcC_virtual-distance)*SIN($E7) -> 10.26521 | Q7: =N7+time -> 4.3652872 | R7: =POWER((POWER((S7-L7),2)+POWER((T7-M7),2)),0.5) -> 5.8212039 | S7: 0 | T7: =T8+Spacing_row1 -> 11 | U7: =R7*1000/sos -> 16.940818 | V7: =distance -> 1.5 | W7: =(T7*(-AcC_row2+distance))/-AcC_row2 -> 12.493128 | X7: =((1000*(distance/COS(E7)))/sos)+U7 -> 26.458515 | Y7: -6.5 | Z7: =IF(Spkr_in_row1>=11,1,0) -> 0 | AB7: Array direction | AC7: =userDirection -> 0 | AD7: =IF(AND(ArrayAngle>120,MainSwtch=2),"don’t go over 120dg","dg") -> dg | AE7: seru | AF7: 2/3 λ | AG7: =AG6*(2/3) -> 114.54 | AH7: =AH6*(2/3) -> 100.85064 | AI7: =AI6*(2/3) -> 99.667111 | AJ7: Hz
C8: =IF(MOD(Spkr_in_row1,2)=1,4,5) -> 5 | D8: =D9+Single_splay -> 51.3 | E8: =RADIANS(D8) -> 0.89535391 | F8: 0 | G8: =G9+Spacing_row1 -> 9 | H8: 0 | I8: =distance -> 1.5 | J8: =G8 -> 9 | K8: =distance*1000/sos -> 4.3652872 | L8: =ABS(AcC_virtual)*COS($E8)+AcC_virtual -> -3.76702 | M8: =ABS(AcC_virtual)*SIN($E8) -> 7.8448015 | N8: 0 | O8: =ABS(AcC_virtual-distance)*COS($E8)+AcC_virtual -> -2.829156 | P8: =ABS(AcC_virtual-distance)*SIN($E8) -> 9.0154471 | Q8: =N8+time -> 4.3652872 | R8: =POWER((POWER((S8-L8),2)+POWER((T8-M8),2)),0.5) -> 3.9401679 | S8: 0 | T8: =T9+Spacing_row1 -> 9 | U8: =R8*1000/sos -> 11.466643 | V8: =distance -> 1.5 | W8: =(T8*(-AcC_row2+distance))/-AcC_row2 -> 10.22165 | X8: =((1000*(distance/COS(E8)))/sos)+U8 -> 18.448392 | Y8: -4 | Z8: =IF(Spkr_in_row1>=9,1,0) -> 0 | AF8: 1/2 λ | AG8: =AG6*(1/2) -> 85.905 | AH8: =AH6*(1/2) -> 75.637982 | AI8: =AI6*(1/2) -> 74.750333 | AJ8: Hz
C9: =IF(MOD(Spkr_in_row1,2)=1,3,4) -> 4 | D9: =D10+Single_splay -> 39.9 | E9: =RADIANS(D9) -> 0.69638637 | F9: 0 | G9: =G10+Spacing_row1 -> 7 | H9: 0 | I9: =distance -> 1.5 | J9: =G9 -> 7 | K9: =distance*1000/sos -> 4.3652872 | L9: =ABS(AcC_virtual)*COS($E9)+AcC_virtual -> -2.3404305 | M9: =ABS(AcC_virtual)*SIN($E9) -> 6.4477819 | N9: 0 | O9: =ABS(AcC_virtual-distance)*COS($E9)+AcC_virtual -> -1.1896828 | P9: =ABS(AcC_virtual-distance)*SIN($E9) -> 7.4099563 | Q9: =N9+time -> 4.3652872 | R9: =POWER((POWER((S9-L9),2)+POWER((T9-M9),2)),0.5) -> 2.4046954 | S9: 0 | T9: =T10+Spacing_row1 -> 7 | U9: =R9*1000/sos -> 6.9981241 | V9: =distance -> 1.5 | W9: =(T9*(-AcC_row2+distance))/-AcC_row2 -> 7.9501725 | X9: =((1000*(distance/COS(E9)))/sos)+U9 -> 12.688277 | Y9: -2.3 | Z9: =IF(Spkr_in_row1>=7,1,0) -> 0
C10: =IF(MOD(Spkr_in_row1,2)=1,2,3) -> 3 | D10: =D11+Single_splay -> 28.5 | E10: =RADIANS(D10) -> 0.49741884 | F10: 0 | G10: =G11+Spacing_row1 -> 5 | H10: 0 | I10: =distance -> 1.5 | J10: =G10 -> 5 | K10: =distance*1000/sos -> 4.3652872 | L10: =ABS(AcC_virtual)*COS($E10)+AcC_virtual -> -1.2181172 | M10: =ABS(AcC_virtual)*SIN($E10) -> 4.7963479 | N10: 0 | O10: =ABS(AcC_virtual-distance)*COS($E10)+AcC_virtual -> 0.10010848 | P10: =ABS(AcC_virtual-distance)*SIN($E10) -> 5.5120861 | Q10: =N10+time -> 4.3652872 | R10: =POWER((POWER((S10-L10),2)+POWER((T10-M10),2)),0.5) -> 1.2350238 | S10: 0 | T10: =T11+Spacing_row1 -> 5 | U10: =R10*1000/sos -> 3.5941556 | V10: =distance -> 1.5 | W10: =(T10*(-AcC_row2+distance))/-AcC_row2 -> 5.6786946 | X10: =((1000*(distance/COS(E10)))/sos)+U10 -> 8.5613862 | Y10: -1.1 | Z10: =IF(Spkr_in_row1>=5,1,0) -> 1 | AF10: Array length | AG10: =AG5*(Spkr_in_row1-1) -> 10 | AH10: =AH5*(Spkr_in_row1-1) -> 11.357389 | AI10: =AI5*(Spkr_in_row1-1) -> 11.492257 | AJ10: m
C11: =IF(MOD(Spkr_in_row1,2)=1,1,2) -> 2 | D11: =D12+Single_splay -> 17.1 | E11: =RADIANS(D11) -> 0.2984513 | F11: 0 | G11: =G12+Spacing_row1 -> 3 | H11: 0 | I11: =distance -> 1.5 | J11: =G11 -> 3 | K11: =distance*1000/sos -> 4.3652872 | L11: =ABS(AcC_virtual)*COS($E11)+AcC_virtual -> -0.4443638 | M11: =ABS(AcC_virtual)*SIN($E11) -> 2.9556613 | N11: 0 | O11: =ABS(AcC_virtual-distance)*COS($E11)+AcC_virtual -> 0.98932572 | P11: =ABS(AcC_virtual-distance)*SIN($E11) -> 3.3967218 | Q11: =N11+time -> 4.3652872 | R11: =POWER((POWER((S11-L11),2)+POWER((T11-M11),2)),0.5) -> 0.44657038 | S11: 0 | T11: =T12+Spacing_row1 -> 3 | U11: =R11*1000/sos -> 1.2996053 | V11: =distance -> 1.5 | W11: =(T11*(-AcC_row2+distance))/-AcC_row2 -> 3.4072168 | X11: =((1000*(distance/COS(E11)))/sos)+U11 -> 5.8667942 | Y11: -0.4 | Z11: =IF(Spkr_in_row1>=3,1,0) -> 1 | AB11: Array takes | AC11: =IF(OR('EndFire Helper'!S29<=0,'EndFire Helper'!S30<=0),"all",('EndFire Helper'!S24*'EndFire Helper'!S25)/('EndFire Helper'!S30*'EndFire Helper'!S29)) -> 0.014196737 | AD11: of Venue | AF11: λ | AG11: =sos/AG10 -> 34.362 | AH11: =sos/AH10 -> 30.255193 | AI11: =sos/AI10 -> 29.900133 | AJ11: Hz
C12: =IF(MOD(Spkr_in_row1,2)=1,"C",1) -> 1 | D12: =IF(MOD(Spkr_in_row1,2)=0, Single_splay/2, 0)+ArrayDirection -> 5.7 | E12: =RADIANS(D12) -> 0.099483767 | F12: 0 | G12: =IF(MOD(Spkr_in_row1,2)=0, ABS(Spacing_row1/2), 0) -> 1 | H12: 0 | I12: =distance -> 1.5 | J12: =G12 -> 1 | K12: =distance*1000/sos -> 4.3652872 | L12: =ABS(AcC_virtual)*COS($E12)+AcC_virtual -> -0.049700873 | M12: =ABS(AcC_virtual)*SIN($E12) -> 0.99835131 | N12: 0 | O12: =ABS(AcC_virtual-distance)*COS($E12)+AcC_virtual -> 1.4428825 | P12: =ABS(AcC_virtual-distance)*SIN($E12) -> 1.1473309 | Q12: =N12+time -> 4.3652872 | R12: =POWER((POWER((S12-L12),2)+POWER((T12-M12),2)),0.5) -> 0.04972821 | S12: 0 | T12: =IF(MOD(Spkr_in_row1,2)=0, ABS(Spacing_row1/2), 0) -> 1 | U12: =ROUND(R12*1000/sos,0) -> 0 | V12: =distance -> 1.5 | W12: =(T12*(-AcC_row2+distance))/-AcC_row2 -> 1.1357389 | X12: =((1000*(distance/COS(E12)))/sos)+U12 -> 4.3869783 | Y12: 0 | Z12: =IF(Spkr_in_row1>=1,1,0) -> 1
B13: R | C13: 1 | D13: =D12-Single_splay -> -5.7 | E13: =RADIANS(D13) -> -0.099483767 | F13: =F12 -> 0 | G13: =-G12 -> -1 | H13: =H12 -> 0 | I13: =I12 -> 1.5 | J13: =-J12 -> -1 | K13: =K12 -> 4.3652872 | L13: =ABS(AcC_virtual)*COS($E13)+AcC_virtual -> -0.049700873 | M13: =ABS(AcC_virtual)*SIN($E13) -> -0.99835131 | N13: 0 | O13: =ABS(AcC_virtual-distance)*COS($E13)+AcC_virtual -> 1.4428825 | P13: =ABS(AcC_virtual-distance)*SIN($E13) -> -1.1473309 | Q13: =N13+time -> 4.3652872 | R13: =POWER((POWER((S13-L13),2)+POWER((T13-M13),2)),0.5) -> 0.04972821 | S13: =S12 -> 0 | T13: =T12-Spacing_row1 -> -1 | U13: =IF(MOD(Spkr_in_row1,2)=1,R13*1000/sos,ROUND(R13*1000/sos,0)) -> 0 | V13: =V12 -> 1.5 | W13: =(T13*(-AcC_row2+distance))/-AcC_row2 -> -1.1357389 | X13: =((1000*(distance/COS(E13)))/sos)+U13 -> 4.3869783 | Y13: =Y12 -> 0 | Z13: =IF(Spkr_in_row1>=2,1,0) -> 1 | AB13: pom
C14: 2 | D14: =D13-Single_splay -> -17.1 | E14: =RADIANS(D14) -> -0.2984513 | F14: =F11 -> 0 | G14: =-G11 -> -3 | H14: =H11 -> 0 | I14: =I11 -> 1.5 | J14: =-J11 -> -3 | K14: =K11 -> 4.3652872 | L14: =ABS(AcC_virtual)*COS($E14)+AcC_virtual -> -0.4443638 | M14: =ABS(AcC_virtual)*SIN($E14) -> -2.9556613 | N14: 0 | O14: =ABS(AcC_virtual-distance)*COS($E14)+AcC_virtual -> 0.98932572 | P14: =ABS(AcC_virtual-distance)*SIN($E14) -> -3.3967218 | Q14: =N14+time -> 4.3652872 | R14: =POWER((POWER((S14-L14),2)+POWER((T14-M14),2)),0.5) -> 0.44657038 | S14: =S11 -> 0 | T14: =T13-Spacing_row1 -> -3 | U14: =R14*1000/sos -> 1.2996053 | V14: =V11 -> 1.5 | W14: =(T14*(-AcC_row2+distance))/-AcC_row2 -> -3.4072168 | X14: =((1000*(distance/COS(E14)))/sos)+U14 -> 5.8667942 | Y14: =Y11 -> -0.4 | Z14: =IF(Spkr_in_row1>=4,1,0) -> 1 | AB14: Single splay | AC14: =IF(Spkr_in_row1=1,1,ArrayAngle/(Spkr_in_row1-1)) -> 11.4 | AD14: dg
C15: 3 | D15: =D14-Single_splay -> -28.5 | E15: =RADIANS(D15) -> -0.49741884 | F15: =F10 -> 0 | G15: =-G10 -> -5 | H15: =H10 -> 0 | I15: =I10 -> 1.5 | J15: =-J10 -> -5 | K15: =K10 -> 4.3652872 | L15: =ABS(AcC_virtual)*COS($E15)+AcC_virtual -> -1.2181172 | M15: =ABS(AcC_virtual)*SIN($E15) -> -4.7963479 | N15: 0 | O15: =ABS(AcC_virtual-distance)*COS($E15)+AcC_virtual -> 0.10010848 | P15: =ABS(AcC_virtual-distance)*SIN($E15) -> -5.5120861 | Q15: =N15+time -> 4.3652872 | R15: =POWER((POWER((S15-L15),2)+POWER((T15-M15),2)),0.5) -> 1.2350238 | S15: =S10 -> 0 | T15: =T14-Spacing_row1 -> -5 | U15: =R15*1000/sos -> 3.5941556 | V15: =V10 -> 1.5 | W15: =(T15*(-AcC_row2+distance))/-AcC_row2 -> -5.6786946 | X15: =((1000*(distance/COS(E15)))/sos)+U15 -> 8.5613862 | Y15: =Y10 -> -1.1 | Z15: =IF(Spkr_in_row1>=6,1,0) -> 1 | AB15: Acoustic C physical | AC15: =-Spacing_row1/RADIANS(Single_splay) -> -10.051891 | AD15: m
C16: 4 | D16: =D15-Single_splay -> -39.9 | E16: =RADIANS(D16) -> -0.69638637 | F16: =F9 -> 0 | G16: =-G9 -> -7 | H16: =H9 -> 0 | I16: =I9 -> 1.5 | J16: =-J9 -> -7 | K16: =K9 -> 4.3652872 | L16: =ABS(AcC_virtual)*COS($E16)+AcC_virtual -> -2.3404305 | M16: =ABS(AcC_virtual)*SIN($E16) -> -6.4477819 | N16: 0 | O16: =ABS(AcC_virtual-distance)*COS($E16)+AcC_virtual -> -1.1896828 | P16: =ABS(AcC_virtual-distance)*SIN($E16) -> -7.4099563 | Q16: =N16+time -> 4.3652872 | R16: =POWER((POWER((S16-L16),2)+POWER((T16-M16),2)),0.5) -> 2.4046954 | S16: =S9 -> 0 | T16: =T15-Spacing_row1 -> -7 | U16: =R16*1000/sos -> 6.9981241 | V16: =V9 -> 1.5 | W16: =(T16*(-AcC_row2+distance))/-AcC_row2 -> -7.9501725 | X16: =((1000*(distance/COS(E16)))/sos)+U16 -> 12.688277 | Y16: =Y9 -> -2.3 | Z16: =IF(Spkr_in_row1>=8,1,0) -> 0 | AB16: Acoustic C row 2 | AC16: =-((Spkr_in_row1*Spacing_row1)/2)/TAN(RADIANS(ArrayAngle/2)) -> -11.050625 | AD16: m
C17: 5 | D17: =D16-Single_splay -> -51.3 | E17: =RADIANS(D17) -> -0.89535391 | F17: =F8 -> 0 | G17: =-G8 -> -9 | H17: =H8 -> 0 | I17: =I8 -> 1.5 | J17: =-J8 -> -9 | K17: =K8 -> 4.3652872 | L17: =ABS(AcC_virtual)*COS($E17)+AcC_virtual -> -3.76702 | M17: =ABS(AcC_virtual)*SIN($E17) -> -7.8448015 | N17: 0 | O17: =ABS(AcC_virtual-distance)*COS($E17)+AcC_virtual -> -2.829156 | P17: =ABS(AcC_virtual-distance)*SIN($E17) -> -9.0154471 | Q17: =N17+time -> 4.3652872 | R17: =POWER((POWER((S17-L17),2)+POWER((T17-M17),2)),0.5) -> 3.9401679 | S17: =S8 -> 0 | T17: =T16-Spacing_row1 -> -9 | U17: =R17*1000/sos -> 11.466643 | V17: =V8 -> 1.5 | W17: =(T17*(-AcC_row2+distance))/-AcC_row2 -> -10.22165 | X17: =((1000*(distance/COS(E17)))/sos)+U17 -> 18.448392 | Y17: =Y8 -> -4 | Z17: =IF(Spkr_in_row1>=10,1,0) -> 0
C18: 6 | D18: =D17-Single_splay -> -62.7 | E18: =RADIANS(D18) -> -1.0943214 | F18: =F7 -> 0 | G18: =-G7 -> -11 | H18: =H7 -> 0 | I18: =I7 -> 1.5 | J18: =-J7 -> -11 | K18: =K7 -> 4.3652872 | L18: =ABS(AcC_virtual)*COS($E18)+AcC_virtual -> -5.4415957 | M18: =ABS(AcC_virtual)*SIN($E18) -> -8.9322837 | N18: 0 | O18: =ABS(AcC_virtual-distance)*COS($E18)+AcC_virtual -> -4.7536214 | P18: =ABS(AcC_virtual-distance)*SIN($E18) -> -10.26521 | Q18: =N18+time -> 4.3652872 | R18: =POWER((POWER((S18-L18),2)+POWER((T18-M18),2)),0.5) -> 5.8212039 | S18: =S7 -> 0 | T18: =T17-Spacing_row1 -> -11 | U18: =R18*1000/sos -> 16.940818 | V18: =V7 -> 1.5 | W18: =(T18*(-AcC_row2+distance))/-AcC_row2 -> -12.493128 | X18: =((1000*(distance/COS(E18)))/sos)+U18 -> 26.458515 | Y18: =Y7 -> -6.5 | Z18: =IF(Spkr_in_row1>=12,1,0) -> 0 | AB18: Rotation | AC18: =RADIANS(OffsetRotDG) -> 0 | AD18: rad
B21: Offsets
B22: id | F22: row1 0dg | I22: row2 0dg | L22: physical row1 | O22: physical row2 | S22: ROW 1 | V22: ROW 2
D23: rotation | F23: X | G23: Y | H23: delay | I23: X | J23: Y | K23: delay | L23: X | M23: Y | N23: delay | O23: X | P23: Y | Q23: delay | R23: dist 2 r1 | S23: X | T23: Y | U23: delay | V23: X | W23: Y | X23: delay
D24: [dg] | E24: [rad] | F24: [m] | G24: [m] | H24: [ms] | I24: [m] | J24: [m] | K24: [ms] | L24: [m] | M24: [m] | N24: [ms] | O24: [m] | P24: [m] | Q24: [ms] | R24: [m] | S24: [m] | T24: [m] | U24: [ms] | V24: [m] | W24: [m] | X24: [ms]
B25: L | C25: =IF(MOD(Spkr_in_row1,2)=1,5,6) -> 6 | D25: =(D7*RotateSpkr/100)+MOD(OffsetRotDG,360) -> 62.7 | F25: =COS(OffsetRot)*F7-SIN(OffsetRot)*G7+offsetX -> 0 | G25: =SIN(OffsetRot)*F7+COS(OffsetRot)*G7+offsetY -> 11 | H25: =H7+offsetT -> 0 | I25: =COS(OffsetRot)*I7-SIN(OffsetRot)*J7+offsetX -> 1.5 | J25: =SIN(OffsetRot)*I7+COS(OffsetRot)*J7+offsetY -> 11 | K25: =K7+offsetT -> 4.3652872 | L25: =COS(OffsetRot)*L7-SIN(OffsetRot)*M7+offsetX -> -5.4415957 | M25: =SIN(OffsetRot)*L7+COS(OffsetRot)*M7+offsetY -> 8.9322837 | N25: =N7+offsetT -> 0 | O25: =COS(OffsetRot)*O7-SIN(OffsetRot)*P7+offsetX -> -4.7536214 | P25: =SIN(OffsetRot)*O7+COS(OffsetRot)*P7+offsetY -> 10.26521 | Q25: =Q7+offsetT -> 4.3652872 | R25: =POWER((POWER((S25-L25),2)+POWER((T25-M25),2)),0.5) -> 5.8212039 | S25: =COS(OffsetRot)*S7-SIN(OffsetRot)*T7+offsetX -> 0 | T25: =SIN(OffsetRot)*S7+COS(OffsetRot)*T7+offsetY -> 11 | U25: =U7+offsetT -> 16.940818 | V25: =COS(OffsetRot)*V7-SIN(OffsetRot)*W7+offsetX -> 1.5 | W25: =SIN(OffsetRot)*V7+COS(OffsetRot)*W7+offsetY -> 12.493128 | X25: =X7+offsetT -> 26.458515
C26: =IF(MOD(Spkr_in_row1,2)=1,4,5) -> 5 | D26: =(D8*RotateSpkr/100)+MOD(OffsetRotDG,360) -> 51.3 | F26: =COS(OffsetRot)*F8-SIN(OffsetRot)*G8+offsetX -> 0 | G26: =SIN(OffsetRot)*F8+COS(OffsetRot)*G8+offsetY -> 9 | H26: =H8+offsetT -> 0 | I26: =COS(OffsetRot)*I8-SIN(OffsetRot)*J8+offsetX -> 1.5 | J26: =SIN(OffsetRot)*I8+COS(OffsetRot)*J8+offsetY -> 9 | K26: =K8+offsetT -> 4.3652872 | L26: =COS(OffsetRot)*L8-SIN(OffsetRot)*M8+offsetX -> -3.76702 | M26: =SIN(OffsetRot)*L8+COS(OffsetRot)*M8+offsetY -> 7.8448015 | N26: =N8+offsetT -> 0 | O26: =COS(OffsetRot)*O8-SIN(OffsetRot)*P8+offsetX -> -2.829156 | P26: =SIN(OffsetRot)*O8+COS(OffsetRot)*P8+offsetY -> 9.0154471 | Q26: =Q8+offsetT -> 4.3652872 | R26: =POWER((POWER((S26-L26),2)+POWER((T26-M26),2)),0.5) -> 3.9401679 | S26: =COS(OffsetRot)*S8-SIN(OffsetRot)*T8+offsetX -> 0 | T26: =SIN(OffsetRot)*S8+COS(OffsetRot)*T8+offsetY -> 9 | U26: =U8+offsetT -> 11.466643 | V26: =COS(OffsetRot)*V8-SIN(OffsetRot)*W8+offsetX -> 1.5 | W26: =SIN(OffsetRot)*V8+COS(OffsetRot)*W8+offsetY -> 10.22165 | X26: =X8+offsetT -> 18.448392
C27: =IF(MOD(Spkr_in_row1,2)=1,3,4) -> 4 | D27: =(D9*RotateSpkr/100)+MOD(OffsetRotDG,360) -> 39.9 | F27: =COS(OffsetRot)*F9-SIN(OffsetRot)*G9+offsetX -> 0 | G27: =SIN(OffsetRot)*F9+COS(OffsetRot)*G9+offsetY -> 7 | H27: =H9+offsetT -> 0 | I27: =COS(OffsetRot)*I9-SIN(OffsetRot)*J9+offsetX -> 1.5 | J27: =SIN(OffsetRot)*I9+COS(OffsetRot)*J9+offsetY -> 7 | K27: =K9+offsetT -> 4.3652872 | L27: =COS(OffsetRot)*L9-SIN(OffsetRot)*M9+offsetX -> -2.3404305 | M27: =SIN(OffsetRot)*L9+COS(OffsetRot)*M9+offsetY -> 6.4477819 | N27: =N9+offsetT -> 0 | O27: =COS(OffsetRot)*O9-SIN(OffsetRot)*P9+offsetX -> -1.1896828 | P27: =SIN(OffsetRot)*O9+COS(OffsetRot)*P9+offsetY -> 7.4099563 | Q27: =Q9+offsetT -> 4.3652872 | R27: =POWER((POWER((S27-L27),2)+POWER((T27-M27),2)),0.5) -> 2.4046954 | S27: =COS(OffsetRot)*S9-SIN(OffsetRot)*T9+offsetX -> 0 | T27: =SIN(OffsetRot)*S9+COS(OffsetRot)*T9+offsetY -> 7 | U27: =U9+offsetT -> 6.9981241 | V27: =COS(OffsetRot)*V9-SIN(OffsetRot)*W9+offsetX -> 1.5 | W27: =SIN(OffsetRot)*V9+COS(OffsetRot)*W9+offsetY -> 7.9501725 | X27: =X9+offsetT -> 12.688277
C28: =IF(MOD(Spkr_in_row1,2)=1,2,3) -> 3 | D28: =(D10*RotateSpkr/100)+MOD(OffsetRotDG,360) -> 28.5 | F28: =COS(OffsetRot)*F10-SIN(OffsetRot)*G10+offsetX -> 0 | G28: =SIN(OffsetRot)*F10+COS(OffsetRot)*G10+offsetY -> 5 | H28: =H10+offsetT -> 0 | I28: =COS(OffsetRot)*I10-SIN(OffsetRot)*J10+offsetX -> 1.5 | J28: =SIN(OffsetRot)*I10+COS(OffsetRot)*J10+offsetY -> 5 | K28: =K10+offsetT -> 4.3652872 | L28: =COS(OffsetRot)*L10-SIN(OffsetRot)*M10+offsetX -> -1.2181172 | M28: =SIN(OffsetRot)*L10+COS(OffsetRot)*M10+offsetY -> 4.7963479 | N28: =N10+offsetT -> 0 | O28: =COS(OffsetRot)*O10-SIN(OffsetRot)*P10+offsetX -> 0.10010848 | P28: =SIN(OffsetRot)*O10+COS(OffsetRot)*P10+offsetY -> 5.5120861 | Q28: =Q10+offsetT -> 4.3652872 | R28: =POWER((POWER((S28-L28),2)+POWER((T28-M28),2)),0.5) -> 1.2350238 | S28: =COS(OffsetRot)*S10-SIN(OffsetRot)*T10+offsetX -> 0 | T28: =SIN(OffsetRot)*S10+COS(OffsetRot)*T10+offsetY -> 5 | U28: =U10+offsetT -> 3.5941556 | V28: =COS(OffsetRot)*V10-SIN(OffsetRot)*W10+offsetX -> 1.5 | W28: =SIN(OffsetRot)*V10+COS(OffsetRot)*W10+offsetY -> 5.6786946 | X28: =X10+offsetT -> 8.5613862
C29: =IF(MOD(Spkr_in_row1,2)=1,1,2) -> 2 | D29: =(D11*RotateSpkr/100)+MOD(OffsetRotDG,360) -> 17.1 | F29: =COS(OffsetRot)*F11-SIN(OffsetRot)*G11+offsetX -> 0 | G29: =SIN(OffsetRot)*F11+COS(OffsetRot)*G11+offsetY -> 3 | H29: =H11+offsetT -> 0 | I29: =COS(OffsetRot)*I11-SIN(OffsetRot)*J11+offsetX -> 1.5 | J29: =SIN(OffsetRot)*I11+COS(OffsetRot)*J11+offsetY -> 3 | K29: =K11+offsetT -> 4.3652872 | L29: =COS(OffsetRot)*L11-SIN(OffsetRot)*M11+offsetX -> -0.4443638 | M29: =SIN(OffsetRot)*L11+COS(OffsetRot)*M11+offsetY -> 2.9556613 | N29: =N11+offsetT -> 0 | O29: =COS(OffsetRot)*O11-SIN(OffsetRot)*P11+offsetX -> 0.98932572 | P29: =SIN(OffsetRot)*O11+COS(OffsetRot)*P11+offsetY -> 3.3967218 | Q29: =Q11+offsetT -> 4.3652872 | R29: =POWER((POWER((S29-L29),2)+POWER((T29-M29),2)),0.5) -> 0.44657038 | S29: =COS(OffsetRot)*S11-SIN(OffsetRot)*T11+offsetX -> 0 | T29: =SIN(OffsetRot)*S11+COS(OffsetRot)*T11+offsetY -> 3 | U29: =U11+offsetT -> 1.2996053 | V29: =COS(OffsetRot)*V11-SIN(OffsetRot)*W11+offsetX -> 1.5 | W29: =SIN(OffsetRot)*V11+COS(OffsetRot)*W11+offsetY -> 3.4072168 | X29: =X11+offsetT -> 5.8667942
C30: =IF(MOD(Spkr_in_row1,2)=1,"C",1) -> 1 | D30: =(D12*RotateSpkr/100)+MOD(OffsetRotDG,360) -> 5.7 | F30: =COS(OffsetRot)*F12-SIN(OffsetRot)*G12+offsetX -> 0 | G30: =SIN(OffsetRot)*F12+COS(OffsetRot)*G12+offsetY -> 1 | H30: =H12+offsetT -> 0 | I30: =COS(OffsetRot)*I12-SIN(OffsetRot)*J12+offsetX -> 1.5 | J30: =SIN(OffsetRot)*I12+COS(OffsetRot)*J12+offsetY -> 1 | K30: =K12+offsetT -> 4.3652872 | L30: =COS(OffsetRot)*L12-SIN(OffsetRot)*M12+offsetX -> -0.049700873 | M30: =SIN(OffsetRot)*L12+COS(OffsetRot)*M12+offsetY -> 0.99835131 | N30: =N12+offsetT -> 0 | O30: =COS(OffsetRot)*O12-SIN(OffsetRot)*P12+offsetX -> 1.4428825 | P30: =SIN(OffsetRot)*O12+COS(OffsetRot)*P12+offsetY -> 1.1473309 | Q30: =Q12+offsetT -> 4.3652872 | R30: =POWER((POWER((S30-L30),2)+POWER((T30-M30),2)),0.5) -> 0.04972821 | S30: =COS(OffsetRot)*S12-SIN(OffsetRot)*T12+offsetX -> 0 | T30: =SIN(OffsetRot)*S12+COS(OffsetRot)*T12+offsetY -> 1 | U30: =U12+offsetT -> 0 | V30: =COS(OffsetRot)*V12-SIN(OffsetRot)*W12+offsetX -> 1.5 | W30: =SIN(OffsetRot)*V12+COS(OffsetRot)*W12+offsetY -> 1.1357389 | X30: =X12+offsetT -> 4.3869783
B31: R | C31: =C30 -> 1 | D31: =(D13*RotateSpkr/100)+MOD(OffsetRotDG,360) -> -5.7 | F31: =COS(OffsetRot)*F13-SIN(OffsetRot)*G13+offsetX -> 0 | G31: =SIN(OffsetRot)*F13+COS(OffsetRot)*G13+offsetY -> -1 | H31: =H13+offsetT -> 0 | I31: =COS(OffsetRot)*I13-SIN(OffsetRot)*J13+offsetX -> 1.5 | J31: =SIN(OffsetRot)*I13+COS(OffsetRot)*J13+offsetY -> -1 | K31: =K13+offsetT -> 4.3652872 | L31: =COS(OffsetRot)*L13-SIN(OffsetRot)*M13+offsetX -> -0.049700873 | M31: =SIN(OffsetRot)*L13+COS(OffsetRot)*M13+offsetY -> -0.99835131 | N31: =N13+offsetT -> 0 | O31: =COS(OffsetRot)*O13-SIN(OffsetRot)*P13+offsetX -> 1.4428825 | P31: =SIN(OffsetRot)*O13+COS(OffsetRot)*P13+offsetY -> -1.1473309 | Q31: =Q13+offsetT -> 4.3652872 | S31: =COS(OffsetRot)*S13-SIN(OffsetRot)*T13+offsetX -> 0 | T31: =SIN(OffsetRot)*S13+COS(OffsetRot)*T13+offsetY -> -1 | U31: =U13+offsetT -> 0 | V31: =COS(OffsetRot)*V13-SIN(OffsetRot)*W13+offsetX -> 1.5 | W31: =SIN(OffsetRot)*V13+COS(OffsetRot)*W13+offsetY -> -1.1357389 | X31: =X13+offsetT -> 4.3869783
C32: =C29 -> 2 | D32: =(D14*RotateSpkr/100)+MOD(OffsetRotDG,360) -> -17.1 | F32: =COS(OffsetRot)*F14-SIN(OffsetRot)*G14+offsetX -> 0 | G32: =SIN(OffsetRot)*F14+COS(OffsetRot)*G14+offsetY -> -3 | H32: =H14+offsetT -> 0 | I32: =COS(OffsetRot)*I14-SIN(OffsetRot)*J14+offsetX -> 1.5 | J32: =SIN(OffsetRot)*I14+COS(OffsetRot)*J14+offsetY -> -3 | K32: =K14+offsetT -> 4.3652872 | L32: =COS(OffsetRot)*L14-SIN(OffsetRot)*M14+offsetX -> -0.4443638 | M32: =SIN(OffsetRot)*L14+COS(OffsetRot)*M14+offsetY -> -2.9556613 | N32: =N14+offsetT -> 0 | O32: =COS(OffsetRot)*O14-SIN(OffsetRot)*P14+offsetX -> 0.98932572 | P32: =SIN(OffsetRot)*O14+COS(OffsetRot)*P14+offsetY -> -3.3967218 | Q32: =Q14+offsetT -> 4.3652872 | S32: =COS(OffsetRot)*S14-SIN(OffsetRot)*T14+offsetX -> 0 | T32: =SIN(OffsetRot)*S14+COS(OffsetRot)*T14+offsetY -> -3 | U32: =U14+offsetT -> 1.2996053 | V32: =COS(OffsetRot)*V14-SIN(OffsetRot)*W14+offsetX -> 1.5 | W32: =SIN(OffsetRot)*V14+COS(OffsetRot)*W14+offsetY -> -3.4072168 | X32: =X14+offsetT -> 5.8667942
C33: =C28 -> 3 | D33: =(D15*RotateSpkr/100)+MOD(OffsetRotDG,360) -> -28.5 | F33: =COS(OffsetRot)*F15-SIN(OffsetRot)*G15+offsetX -> 0 | G33: =SIN(OffsetRot)*F15+COS(OffsetRot)*G15+offsetY -> -5 | H33: =H15+offsetT -> 0 | I33: =COS(OffsetRot)*I15-SIN(OffsetRot)*J15+offsetX -> 1.5 | J33: =SIN(OffsetRot)*I15+COS(OffsetRot)*J15+offsetY -> -5 | K33: =K15+offsetT -> 4.3652872 | L33: =COS(OffsetRot)*L15-SIN(OffsetRot)*M15+offsetX -> -1.2181172 | M33: =SIN(OffsetRot)*L15+COS(OffsetRot)*M15+offsetY -> -4.7963479 | N33: =N15+offsetT -> 0 | O33: =COS(OffsetRot)*O15-SIN(OffsetRot)*P15+offsetX -> 0.10010848 | P33: =SIN(OffsetRot)*O15+COS(OffsetRot)*P15+offsetY -> -5.5120861 | Q33: =Q15+offsetT -> 4.3652872 | S33: =COS(OffsetRot)*S15-SIN(OffsetRot)*T15+offsetX -> 0 | T33: =SIN(OffsetRot)*S15+COS(OffsetRot)*T15+offsetY -> -5 | U33: =U15+offsetT -> 3.5941556 | V33: =COS(OffsetRot)*V15-SIN(OffsetRot)*W15+offsetX -> 1.5 | W33: =SIN(OffsetRot)*V15+COS(OffsetRot)*W15+offsetY -> -5.6786946 | X33: =X15+offsetT -> 8.5613862
C34: =C27 -> 4 | D34: =(D16*RotateSpkr/100)+MOD(OffsetRotDG,360) -> -39.9 | F34: =COS(OffsetRot)*F16-SIN(OffsetRot)*G16+offsetX -> 0 | G34: =SIN(OffsetRot)*F16+COS(OffsetRot)*G16+offsetY -> -7 | H34: =H16+offsetT -> 0 | I34: =COS(OffsetRot)*I16-SIN(OffsetRot)*J16+offsetX -> 1.5 | J34: =SIN(OffsetRot)*I16+COS(OffsetRot)*J16+offsetY -> -7 | K34: =K16+offsetT -> 4.3652872 | L34: =COS(OffsetRot)*L16-SIN(OffsetRot)*M16+offsetX -> -2.3404305 | M34: =SIN(OffsetRot)*L16+COS(OffsetRot)*M16+offsetY -> -6.4477819 | N34: =N16+offsetT -> 0 | O34: =COS(OffsetRot)*O16-SIN(OffsetRot)*P16+offsetX -> -1.1896828 | P34: =SIN(OffsetRot)*O16+COS(OffsetRot)*P16+offsetY -> -7.4099563 | Q34: =Q16+offsetT -> 4.3652872 | S34: =COS(OffsetRot)*S16-SIN(OffsetRot)*T16+offsetX -> 0 | T34: =SIN(OffsetRot)*S16+COS(OffsetRot)*T16+offsetY -> -7 | U34: =U16+offsetT -> 6.9981241 | V34: =COS(OffsetRot)*V16-SIN(OffsetRot)*W16+offsetX -> 1.5 | W34: =SIN(OffsetRot)*V16+COS(OffsetRot)*W16+offsetY -> -7.9501725 | X34: =X16+offsetT -> 12.688277
C35: =C26 -> 5 | D35: =(D17*RotateSpkr/100)+MOD(OffsetRotDG,360) -> -51.3 | F35: =COS(OffsetRot)*F17-SIN(OffsetRot)*G17+offsetX -> 0 | G35: =SIN(OffsetRot)*F17+COS(OffsetRot)*G17+offsetY -> -9 | H35: =H17+offsetT -> 0 | I35: =COS(OffsetRot)*I17-SIN(OffsetRot)*J17+offsetX -> 1.5 | J35: =SIN(OffsetRot)*I17+COS(OffsetRot)*J17+offsetY -> -9 | K35: =K17+offsetT -> 4.3652872 | L35: =COS(OffsetRot)*L17-SIN(OffsetRot)*M17+offsetX -> -3.76702 | M35: =SIN(OffsetRot)*L17+COS(OffsetRot)*M17+offsetY -> -7.8448015 | N35: =N17+offsetT -> 0 | O35: =COS(OffsetRot)*O17-SIN(OffsetRot)*P17+offsetX -> -2.829156 | P35: =SIN(OffsetRot)*O17+COS(OffsetRot)*P17+offsetY -> -9.0154471 | Q35: =Q17+offsetT -> 4.3652872 | S35: =COS(OffsetRot)*S17-SIN(OffsetRot)*T17+offsetX -> 0 | T35: =SIN(OffsetRot)*S17+COS(OffsetRot)*T17+offsetY -> -9 | U35: =U17+offsetT -> 11.466643 | V35: =COS(OffsetRot)*V17-SIN(OffsetRot)*W17+offsetX -> 1.5 | W35: =SIN(OffsetRot)*V17+COS(OffsetRot)*W17+offsetY -> -10.22165 | X35: =X17+offsetT -> 18.448392
C36: =C25 -> 6 | D36: =(D18*RotateSpkr/100)+MOD(OffsetRotDG,360) -> -62.7 | F36: =COS(OffsetRot)*F18-SIN(OffsetRot)*G18+offsetX -> 0 | G36: =SIN(OffsetRot)*F18+COS(OffsetRot)*G18+offsetY -> -11 | H36: =H18+offsetT -> 0 | I36: =COS(OffsetRot)*I18-SIN(OffsetRot)*J18+offsetX -> 1.5 | J36: =SIN(OffsetRot)*I18+COS(OffsetRot)*J18+offsetY -> -11 | K36: =K18+offsetT -> 4.3652872 | L36: =COS(OffsetRot)*L18-SIN(OffsetRot)*M18+offsetX -> -5.4415957 | M36: =SIN(OffsetRot)*L18+COS(OffsetRot)*M18+offsetY -> -8.9322837 | N36: =N18+offsetT -> 0 | O36: =COS(OffsetRot)*O18-SIN(OffsetRot)*P18+offsetX -> -4.7536214 | P36: =SIN(OffsetRot)*O18+COS(OffsetRot)*P18+offsetY -> -10.26521 | Q36: =Q18+offsetT -> 4.3652872 | S36: =COS(OffsetRot)*S18-SIN(OffsetRot)*T18+offsetX -> 0 | T36: =SIN(OffsetRot)*S18+COS(OffsetRot)*T18+offsetY -> -11 | U36: =U18+offsetT -> 16.940818 | V36: =COS(OffsetRot)*V18-SIN(OffsetRot)*W18+offsetX -> 1.5 | W36: =SIN(OffsetRot)*V18+COS(OffsetRot)*W18+offsetY -> -12.493128 | X36: =X18+offsetT -> 26.458515
B39: Cancelation differences | M39: Graph
B40: id | D40: row 1 to row 2 physical | G40: row 1 to row 2 lines | M40: ROW 1 | P40: ROW 2
D41: distance | E41: time | F41: 1/4 λ | G41: distance | H41: freq | I41: 1/4 λ | J41: diff | M41: X | N41: Y | P41: X | Q41: Y
D42: [m] | E42: [ms] | F42: [Hz] | G42: [m] | H42: [ms] | I42: [Hz] | J42: [%] | M42: [m] | N42: [m] | P42: [m] | Q42: [m]
B43: L | C43: =IF(MOD(Spkr_in_row1,2)=1,5,6) -> 6 | D43: =distance -> 1.5 | E43: =distance*1000/sos -> 4.3652872 | F43: =sos/D43/4 -> 57.27 | G43: =POWER((POWER((S7-V7),2)+POWER((T7-W7),2)),0.5) -> 2.1164668 | H43: =G43*1000/sos -> 6.1593237 | I43: =sos/G43/4 -> 40.588872 | J43: =H43/E43-1 -> 0.41097787 | M43: =IF('EndFire Helper'!E8="",-50,'EndFire Helper'!E8) -> -50 | N43: =IF('EndFire Helper'!F8="",0,'EndFire Helper'!F8) -> 0 | P43: =IF('EndFire Helper'!H8="",-50,'EndFire Helper'!H8) -> -50 | Q43: =IF('EndFire Helper'!I8="",0,'EndFire Helper'!I8) -> 0
C44: =IF(MOD(Spkr_in_row1,2)=1,4,5) -> 5 | D44: =distance -> 1.5 | E44: =distance*1000/sos -> 4.3652872 | F44: =sos/D44/4 -> 57.27 | G44: =POWER((POWER((S8-V8),2)+POWER((T8-W8),2)),0.5) -> 1.934536 | H44: =G44*1000/sos -> 5.6298702 | I44: =sos/G44/4 -> 44.405997 | J44: =H44/E44-1 -> 0.28969066 | M44: =IF('EndFire Helper'!E9="",-50,'EndFire Helper'!E9) -> -50 | N44: =IF('EndFire Helper'!F9="",0,'EndFire Helper'!F9) -> 0 | P44: =IF('EndFire Helper'!H9="",-50,'EndFire Helper'!H9) -> -50 | Q44: =IF('EndFire Helper'!I9="",0,'EndFire Helper'!I9) -> 0
C45: =IF(MOD(Spkr_in_row1,2)=1,3,4) -> 4 | D45: =distance -> 1.5 | E45: =distance*1000/sos -> 4.3652872 | F45: =sos/D45/4 -> 57.27 | G45: =POWER((POWER((S9-V9),2)+POWER((T9-W9),2)),0.5) -> 1.7756204 | H45: =G45*1000/sos -> 5.1673953 | I45: =sos/G45/4 -> 48.380274 | J45: =H45/E45-1 -> 0.18374692 | M45: =IF('EndFire Helper'!E10="",-50,'EndFire Helper'!E10) -> -50 | N45: =IF('EndFire Helper'!F10="",0,'EndFire Helper'!F10) -> 0 | P45: =IF('EndFire Helper'!H10="",-50,'EndFire Helper'!H10) -> -50 | Q45: =IF('EndFire Helper'!I10="",0,'EndFire Helper'!I10) -> 0
C46: =IF(MOD(Spkr_in_row1,2)=1,2,3) -> 3 | D46: =distance -> 1.5 | E46: =distance*1000/sos -> 4.3652872 | F46: =sos/D46/4 -> 57.27 | G46: =POWER((POWER((S10-V10),2)+POWER((T10-W10),2)),0.5) -> 1.646398 | H46: =G46*1000/sos -> 4.7913335 | I46: =sos/G46/4 -> 52.177541 | J46: =H46/E46-1 -> 0.097598671 | M46: =IF('EndFire Helper'!E11="",-50,'EndFire Helper'!E11) -> 0 | N46: =IF('EndFire Helper'!F11="",0,'EndFire Helper'!F11) -> 5 | P46: =IF('EndFire Helper'!H11="",-50,'EndFire Helper'!H11) -> 1.5 | Q46: =IF('EndFire Helper'!I11="",0,'EndFire Helper'!I11) -> 5.6786946
...
